[2023-03-25T21:24:52.889+0000] {taskinstance.py:1084} INFO - Dependencies all met for dep_context=non-requeueable deps ti=<TaskInstance: get_weather_data_v0.download_weather_data scheduled__2023-03-25T20:00:00+00:00 [queued]>
[2023-03-25T21:24:52.899+0000] {taskinstance.py:1084} INFO - Dependencies all met for dep_context=requeueable deps ti=<TaskInstance: get_weather_data_v0.download_weather_data scheduled__2023-03-25T20:00:00+00:00 [queued]>
[2023-03-25T21:24:52.899+0000] {taskinstance.py:1282} INFO - 
--------------------------------------------------------------------------------
[2023-03-25T21:24:52.899+0000] {taskinstance.py:1283} INFO - Starting attempt 1 of 6
[2023-03-25T21:24:52.899+0000] {taskinstance.py:1284} INFO - 
--------------------------------------------------------------------------------
[2023-03-25T21:24:52.911+0000] {taskinstance.py:1303} INFO - Executing <Task(PythonOperator): download_weather_data> on 2023-03-25 20:00:00+00:00
[2023-03-25T21:24:52.915+0000] {standard_task_runner.py:55} INFO - Started process 188 to run task
[2023-03-25T21:24:52.918+0000] {standard_task_runner.py:82} INFO - Running: ['***', 'tasks', 'run', 'get_weather_data_v0', 'download_weather_data', 'scheduled__2023-03-25T20:00:00+00:00', '--job-id', '7', '--raw', '--subdir', 'DAGS_FOLDER/get_weather_data.py', '--cfg-path', '/tmp/tmpf5mfv5un']
[2023-03-25T21:24:52.920+0000] {standard_task_runner.py:83} INFO - Job 7: Subtask download_weather_data
[2023-03-25T21:24:53.017+0000] {task_command.py:388} INFO - Running <TaskInstance: get_weather_data_v0.download_weather_data scheduled__2023-03-25T20:00:00+00:00 [running]> on host c8652e9a453c
[2023-03-25T21:24:53.120+0000] {taskinstance.py:1511} INFO - Exporting the following env vars:
AIRFLOW_CTX_DAG_OWNER=AlexDeLara
AIRFLOW_CTX_DAG_ID=get_weather_data_v0
AIRFLOW_CTX_TASK_ID=download_weather_data
AIRFLOW_CTX_EXECUTION_DATE=2023-03-25T20:00:00+00:00
AIRFLOW_CTX_TRY_NUMBER=1
AIRFLOW_CTX_DAG_RUN_ID=scheduled__2023-03-25T20:00:00+00:00
[2023-03-25T21:24:53.638+0000] {get_weather_data.py:48} INFO - Decompressing .gz weather data...
[2023-03-25T21:24:53.672+0000] {get_weather_data.py:50} INFO - Decompression successful!
[2023-03-25T21:24:53.672+0000] {get_weather_data.py:57} INFO - Parsing json weather data...
[2023-03-25T21:24:53.814+0000] {get_weather_data.py:59} INFO - Parsing successful!
[2023-03-25T21:24:53.815+0000] {get_weather_data.py:72} INFO - Writing current data...
[2023-03-25T21:24:53.914+0000] {get_weather_data.py:88} ERROR - An error occurred when trying to retrieve the weather data. Error:
[Errno 13] Permission denied: '/data/weather/raw/current_weather_data.parquet'
[2023-03-25T21:24:53.914+0000] {taskinstance.py:1775} ERROR - Task failed with exception
Traceback (most recent call last):
  File "/home/airflow/.local/lib/python3.7/site-packages/airflow/operators/python.py", line 175, in execute
    return_value = self.execute_callable()
  File "/home/airflow/.local/lib/python3.7/site-packages/airflow/operators/python.py", line 192, in execute_callable
    return self.python_callable(*self.op_args, **self.op_kwargs)
  File "/opt/airflow/dags/get_weather_data.py", line 73, in download_weather_data
    data.to_parquet(path=f"{base_output_path}/raw/current_weather_data.parquet", index=False)
  File "/home/airflow/.local/lib/python3.7/site-packages/pandas/util/_decorators.py", line 207, in wrapper
    return func(*args, **kwargs)
  File "/home/airflow/.local/lib/python3.7/site-packages/pandas/core/frame.py", line 2685, in to_parquet
    **kwargs,
  File "/home/airflow/.local/lib/python3.7/site-packages/pandas/io/parquet.py", line 423, in to_parquet
    **kwargs,
  File "/home/airflow/.local/lib/python3.7/site-packages/pandas/io/parquet.py", line 180, in write
    is_dir=partition_cols is not None,
  File "/home/airflow/.local/lib/python3.7/site-packages/pandas/io/parquet.py", line 102, in _get_path_or_handle
    path_or_handle, mode, is_text=False, storage_options=storage_options
  File "/home/airflow/.local/lib/python3.7/site-packages/pandas/io/common.py", line 711, in get_handle
    handle = open(handle, ioargs.mode)
PermissionError: [Errno 13] Permission denied: '/data/weather/raw/current_weather_data.parquet'
[2023-03-25T21:24:53.923+0000] {taskinstance.py:1326} INFO - Marking task as UP_FOR_RETRY. dag_id=get_weather_data_v0, task_id=download_weather_data, execution_date=20230325T200000, start_date=20230325T212452, end_date=20230325T212453
[2023-03-25T21:24:53.938+0000] {standard_task_runner.py:105} ERROR - Failed to execute job 7 for task download_weather_data ([Errno 13] Permission denied: '/data/weather/raw/current_weather_data.parquet'; 188)
[2023-03-25T21:24:53.972+0000] {local_task_job.py:212} INFO - Task exited with return code 1
[2023-03-25T21:24:53.999+0000] {taskinstance.py:2585} INFO - 0 downstream tasks scheduled from follow-on schedule check
[2023-03-25T21:27:20.580+0000] {taskinstance.py:1084} INFO - Dependencies all met for dep_context=non-requeueable deps ti=<TaskInstance: get_weather_data_v0.download_weather_data scheduled__2023-03-25T20:00:00+00:00 [queued]>
[2023-03-25T21:27:20.605+0000] {taskinstance.py:1084} INFO - Dependencies all met for dep_context=requeueable deps ti=<TaskInstance: get_weather_data_v0.download_weather_data scheduled__2023-03-25T20:00:00+00:00 [queued]>
[2023-03-25T21:27:20.605+0000] {taskinstance.py:1282} INFO - 
--------------------------------------------------------------------------------
[2023-03-25T21:27:20.606+0000] {taskinstance.py:1283} INFO - Starting attempt 1 of 6
[2023-03-25T21:27:20.606+0000] {taskinstance.py:1284} INFO - 
--------------------------------------------------------------------------------
[2023-03-25T21:27:20.626+0000] {taskinstance.py:1303} INFO - Executing <Task(PythonOperator): download_weather_data> on 2023-03-25 20:00:00+00:00
[2023-03-25T21:27:20.633+0000] {standard_task_runner.py:55} INFO - Started process 201 to run task
[2023-03-25T21:27:20.638+0000] {standard_task_runner.py:82} INFO - Running: ['***', 'tasks', 'run', 'get_weather_data_v0', 'download_weather_data', 'scheduled__2023-03-25T20:00:00+00:00', '--job-id', '3', '--raw', '--subdir', 'DAGS_FOLDER/get_weather_data.py', '--cfg-path', '/tmp/tmppkvksp0w']
[2023-03-25T21:27:20.641+0000] {standard_task_runner.py:83} INFO - Job 3: Subtask download_weather_data
[2023-03-25T21:27:20.741+0000] {task_command.py:388} INFO - Running <TaskInstance: get_weather_data_v0.download_weather_data scheduled__2023-03-25T20:00:00+00:00 [running]> on host a02366003eff
[2023-03-25T21:27:20.853+0000] {taskinstance.py:1511} INFO - Exporting the following env vars:
AIRFLOW_CTX_DAG_OWNER=AlexDeLara
AIRFLOW_CTX_DAG_ID=get_weather_data_v0
AIRFLOW_CTX_TASK_ID=download_weather_data
AIRFLOW_CTX_EXECUTION_DATE=2023-03-25T20:00:00+00:00
AIRFLOW_CTX_TRY_NUMBER=1
AIRFLOW_CTX_DAG_RUN_ID=scheduled__2023-03-25T20:00:00+00:00
[2023-03-25T21:27:20.945+0000] {get_weather_data.py:48} INFO - Decompressing .gz weather data...
[2023-03-25T21:27:20.964+0000] {get_weather_data.py:50} INFO - Decompression successful!
[2023-03-25T21:27:20.965+0000] {get_weather_data.py:57} INFO - Parsing json weather data...
[2023-03-25T21:27:21.189+0000] {get_weather_data.py:59} INFO - Parsing successful!
[2023-03-25T21:27:21.192+0000] {get_weather_data.py:72} INFO - Writing current data...
[2023-03-25T21:27:21.315+0000] {get_weather_data.py:88} ERROR - An error occurred when trying to retrieve the weather data. Error:
[Errno 13] Permission denied: '/data/weather/raw/current_weather_data.parquet'
[2023-03-25T21:27:21.315+0000] {taskinstance.py:1775} ERROR - Task failed with exception
Traceback (most recent call last):
  File "/home/airflow/.local/lib/python3.7/site-packages/airflow/operators/python.py", line 175, in execute
    return_value = self.execute_callable()
  File "/home/airflow/.local/lib/python3.7/site-packages/airflow/operators/python.py", line 192, in execute_callable
    return self.python_callable(*self.op_args, **self.op_kwargs)
  File "/opt/airflow/dags/get_weather_data.py", line 73, in download_weather_data
    data.to_parquet(path=f"{base_output_path}/raw/current_weather_data.parquet", index=False)
  File "/home/airflow/.local/lib/python3.7/site-packages/pandas/util/_decorators.py", line 207, in wrapper
    return func(*args, **kwargs)
  File "/home/airflow/.local/lib/python3.7/site-packages/pandas/core/frame.py", line 2685, in to_parquet
    **kwargs,
  File "/home/airflow/.local/lib/python3.7/site-packages/pandas/io/parquet.py", line 423, in to_parquet
    **kwargs,
  File "/home/airflow/.local/lib/python3.7/site-packages/pandas/io/parquet.py", line 180, in write
    is_dir=partition_cols is not None,
  File "/home/airflow/.local/lib/python3.7/site-packages/pandas/io/parquet.py", line 102, in _get_path_or_handle
    path_or_handle, mode, is_text=False, storage_options=storage_options
  File "/home/airflow/.local/lib/python3.7/site-packages/pandas/io/common.py", line 711, in get_handle
    handle = open(handle, ioargs.mode)
PermissionError: [Errno 13] Permission denied: '/data/weather/raw/current_weather_data.parquet'
[2023-03-25T21:27:21.328+0000] {taskinstance.py:1326} INFO - Marking task as UP_FOR_RETRY. dag_id=get_weather_data_v0, task_id=download_weather_data, execution_date=20230325T200000, start_date=20230325T212720, end_date=20230325T212721
[2023-03-25T21:27:21.344+0000] {standard_task_runner.py:105} ERROR - Failed to execute job 3 for task download_weather_data ([Errno 13] Permission denied: '/data/weather/raw/current_weather_data.parquet'; 201)
[2023-03-25T21:27:21.370+0000] {local_task_job.py:212} INFO - Task exited with return code 1
[2023-03-25T21:27:21.421+0000] {taskinstance.py:2585} INFO - 0 downstream tasks scheduled from follow-on schedule check
[2023-03-25T21:36:39.182+0000] {taskinstance.py:1084} INFO - Dependencies all met for dep_context=non-requeueable deps ti=<TaskInstance: get_weather_data_v0.download_weather_data scheduled__2023-03-25T20:00:00+00:00 [queued]>
[2023-03-25T21:36:39.195+0000] {taskinstance.py:1084} INFO - Dependencies all met for dep_context=requeueable deps ti=<TaskInstance: get_weather_data_v0.download_weather_data scheduled__2023-03-25T20:00:00+00:00 [queued]>
[2023-03-25T21:36:39.196+0000] {taskinstance.py:1282} INFO - 
--------------------------------------------------------------------------------
[2023-03-25T21:36:39.196+0000] {taskinstance.py:1283} INFO - Starting attempt 1 of 6
[2023-03-25T21:36:39.196+0000] {taskinstance.py:1284} INFO - 
--------------------------------------------------------------------------------
[2023-03-25T21:36:39.215+0000] {taskinstance.py:1303} INFO - Executing <Task(PythonOperator): download_weather_data> on 2023-03-25 20:00:00+00:00
[2023-03-25T21:36:39.221+0000] {standard_task_runner.py:55} INFO - Started process 201 to run task
[2023-03-25T21:36:39.225+0000] {standard_task_runner.py:82} INFO - Running: ['***', 'tasks', 'run', 'get_weather_data_v0', 'download_weather_data', 'scheduled__2023-03-25T20:00:00+00:00', '--job-id', '3', '--raw', '--subdir', 'DAGS_FOLDER/get_weather_data.py', '--cfg-path', '/tmp/tmpl62hczwa']
[2023-03-25T21:36:39.227+0000] {standard_task_runner.py:83} INFO - Job 3: Subtask download_weather_data
[2023-03-25T21:36:39.304+0000] {task_command.py:388} INFO - Running <TaskInstance: get_weather_data_v0.download_weather_data scheduled__2023-03-25T20:00:00+00:00 [running]> on host 8647624ffe94
[2023-03-25T21:36:39.409+0000] {taskinstance.py:1511} INFO - Exporting the following env vars:
AIRFLOW_CTX_DAG_OWNER=AlexDeLara
AIRFLOW_CTX_DAG_ID=get_weather_data_v0
AIRFLOW_CTX_TASK_ID=download_weather_data
AIRFLOW_CTX_EXECUTION_DATE=2023-03-25T20:00:00+00:00
AIRFLOW_CTX_TRY_NUMBER=1
AIRFLOW_CTX_DAG_RUN_ID=scheduled__2023-03-25T20:00:00+00:00
[2023-03-25T21:36:39.920+0000] {get_weather_data.py:48} INFO - Decompressing .gz weather data...
[2023-03-25T21:36:39.956+0000] {get_weather_data.py:50} INFO - Decompression successful!
[2023-03-25T21:36:39.957+0000] {get_weather_data.py:57} INFO - Parsing json weather data...
[2023-03-25T21:36:40.137+0000] {get_weather_data.py:59} INFO - Parsing successful!
[2023-03-25T21:36:40.140+0000] {get_weather_data.py:72} INFO - Writing current data...
[2023-03-25T21:36:40.306+0000] {get_weather_data.py:74} INFO - Successfully created current_weather_data.parquet file!...
[2023-03-25T21:36:40.306+0000] {get_weather_data.py:76} INFO - Appending to historic data...
[2023-03-25T21:36:40.307+0000] {get_weather_data.py:88} ERROR - An error occurred when trying to retrieve the weather data. Error:
[Errno 2] No such file or directory: '/opt/***/dags/data//raw/historic_weather_data.parquet'
[2023-03-25T21:36:40.307+0000] {taskinstance.py:1775} ERROR - Task failed with exception
Traceback (most recent call last):
  File "/home/airflow/.local/lib/python3.7/site-packages/airflow/operators/python.py", line 175, in execute
    return_value = self.execute_callable()
  File "/home/airflow/.local/lib/python3.7/site-packages/airflow/operators/python.py", line 192, in execute_callable
    return self.python_callable(*self.op_args, **self.op_kwargs)
  File "/opt/airflow/dags/get_weather_data.py", line 78, in download_weather_data
    history = pd.read_parquet(path=f"{base_output_path}/raw/historic_weather_data.parquet")
  File "/home/airflow/.local/lib/python3.7/site-packages/pandas/io/parquet.py", line 500, in read_parquet
    **kwargs,
  File "/home/airflow/.local/lib/python3.7/site-packages/pandas/io/parquet.py", line 236, in read
    mode="rb",
  File "/home/airflow/.local/lib/python3.7/site-packages/pandas/io/parquet.py", line 102, in _get_path_or_handle
    path_or_handle, mode, is_text=False, storage_options=storage_options
  File "/home/airflow/.local/lib/python3.7/site-packages/pandas/io/common.py", line 711, in get_handle
    handle = open(handle, ioargs.mode)
FileNotFoundError: [Errno 2] No such file or directory: '/opt/airflow/dags/data//raw/historic_weather_data.parquet'
[2023-03-25T21:36:40.320+0000] {taskinstance.py:1326} INFO - Marking task as UP_FOR_RETRY. dag_id=get_weather_data_v0, task_id=download_weather_data, execution_date=20230325T200000, start_date=20230325T213639, end_date=20230325T213640
[2023-03-25T21:36:40.342+0000] {standard_task_runner.py:105} ERROR - Failed to execute job 3 for task download_weather_data ([Errno 2] No such file or directory: '/opt/airflow/dags/data//raw/historic_weather_data.parquet'; 201)
[2023-03-25T21:36:40.358+0000] {local_task_job.py:212} INFO - Task exited with return code 1
[2023-03-25T21:36:40.394+0000] {taskinstance.py:2585} INFO - 0 downstream tasks scheduled from follow-on schedule check
[2023-03-25T21:55:34.997+0000] {taskinstance.py:1084} INFO - Dependencies all met for dep_context=non-requeueable deps ti=<TaskInstance: get_weather_data_v0.download_weather_data scheduled__2023-03-25T20:00:00+00:00 [queued]>
[2023-03-25T21:55:35.007+0000] {taskinstance.py:1084} INFO - Dependencies all met for dep_context=requeueable deps ti=<TaskInstance: get_weather_data_v0.download_weather_data scheduled__2023-03-25T20:00:00+00:00 [queued]>
[2023-03-25T21:55:35.007+0000] {taskinstance.py:1282} INFO - 
--------------------------------------------------------------------------------
[2023-03-25T21:55:35.007+0000] {taskinstance.py:1283} INFO - Starting attempt 1 of 6
[2023-03-25T21:55:35.008+0000] {taskinstance.py:1284} INFO - 
--------------------------------------------------------------------------------
[2023-03-25T21:55:35.021+0000] {taskinstance.py:1303} INFO - Executing <Task(PythonOperator): download_weather_data> on 2023-03-25 20:00:00+00:00
[2023-03-25T21:55:35.025+0000] {standard_task_runner.py:55} INFO - Started process 201 to run task
[2023-03-25T21:55:35.028+0000] {standard_task_runner.py:82} INFO - Running: ['***', 'tasks', 'run', 'get_weather_data_v0', 'download_weather_data', 'scheduled__2023-03-25T20:00:00+00:00', '--job-id', '3', '--raw', '--subdir', 'DAGS_FOLDER/get_weather_data.py', '--cfg-path', '/tmp/tmpq1xkrf1c']
[2023-03-25T21:55:35.030+0000] {standard_task_runner.py:83} INFO - Job 3: Subtask download_weather_data
[2023-03-25T21:55:35.089+0000] {task_command.py:388} INFO - Running <TaskInstance: get_weather_data_v0.download_weather_data scheduled__2023-03-25T20:00:00+00:00 [running]> on host eb99e9ad14f4
[2023-03-25T21:55:35.185+0000] {taskinstance.py:1511} INFO - Exporting the following env vars:
AIRFLOW_CTX_DAG_OWNER=AlexDeLara
AIRFLOW_CTX_DAG_ID=get_weather_data_v0
AIRFLOW_CTX_TASK_ID=download_weather_data
AIRFLOW_CTX_EXECUTION_DATE=2023-03-25T20:00:00+00:00
AIRFLOW_CTX_TRY_NUMBER=1
AIRFLOW_CTX_DAG_RUN_ID=scheduled__2023-03-25T20:00:00+00:00
[2023-03-25T21:55:35.391+0000] {get_weather_data.py:88} ERROR - An error occurred when trying to retrieve the weather data. Error:
Could not retrieve weather data. Response code: 404.
Response message: <!DOCTYPE html>
<html lang="es-es" dir="ltr">
<head>
	<meta charset="utf-8" />
	<title>404 - Artículo no encontrado</title>
	<link href="/templates/system/css/error.css" rel="stylesheet" />
			<!--[if lt IE 9]><script src="/media/jui/js/html5.js"></script><![endif]-->
</head>
<body>
	<div class="error">
		<div id="outline">
		<div id="errorboxoutline">
			<div id="errorboxheader">404 - Artículo no encontrado</div>
			<div id="errorboxbody">
			<p><strong>No puede visitar esta página debido a:</strong></p>
			<ol>
				<li>Un <strong>marcador o favorito caducado</strong></li>
				<li>Un motor de búsquedas que tiene un <strong>listado caducado para este sitio</strong></li>
				<li>Una <strong>dirección mal escrita</strong></li>
				<li>Usted no tiene <strong>acceso</strong> a esta página</li>
				<li>No se pudo encontrar el recurso solicitado.</li>
				<li>Se ha producido un error mientras se procesaba su solicitud.</li>
			</ol>
			<p><strong>Por favor, pruebe con alguna de las páginas siguientes:</strong></p>
			<ul>
				<li><a href="/index.php" title="Ir a la página de inicio">Página de inicio</a></li>
			</ul>
			<p>Si la dificultad persiste, por favor, contacte con el administrador del sistema de este sitio y reporte el error de más abajo.</p>
			<div id="techinfo">
			<p>
				Artículo no encontrado							</p>
						</div>
			</div>
		</div>
		</div>
	</div>
</body>
</html>

[2023-03-25T21:55:35.392+0000] {taskinstance.py:1775} ERROR - Task failed with exception
Traceback (most recent call last):
  File "/home/airflow/.local/lib/python3.7/site-packages/airflow/operators/python.py", line 175, in execute
    return_value = self.execute_callable()
  File "/home/airflow/.local/lib/python3.7/site-packages/airflow/operators/python.py", line 192, in execute_callable
    return self.python_callable(*self.op_args, **self.op_kwargs)
  File "/opt/airflow/dags/get_weather_data.py", line 85, in download_weather_data
    raise ValueError(f"Could not retrieve weather data. Response code: {response.status_code}.\nResponse message: {response.text}")
ValueError: Could not retrieve weather data. Response code: 404.
Response message: <!DOCTYPE html>
<html lang="es-es" dir="ltr">
<head>
	<meta charset="utf-8" />
	<title>404 - Artículo no encontrado</title>
	<link href="/templates/system/css/error.css" rel="stylesheet" />
			<!--[if lt IE 9]><script src="/media/jui/js/html5.js"></script><![endif]-->
</head>
<body>
	<div class="error">
		<div id="outline">
		<div id="errorboxoutline">
			<div id="errorboxheader">404 - Artículo no encontrado</div>
			<div id="errorboxbody">
			<p><strong>No puede visitar esta página debido a:</strong></p>
			<ol>
				<li>Un <strong>marcador o favorito caducado</strong></li>
				<li>Un motor de búsquedas que tiene un <strong>listado caducado para este sitio</strong></li>
				<li>Una <strong>dirección mal escrita</strong></li>
				<li>Usted no tiene <strong>acceso</strong> a esta página</li>
				<li>No se pudo encontrar el recurso solicitado.</li>
				<li>Se ha producido un error mientras se procesaba su solicitud.</li>
			</ol>
			<p><strong>Por favor, pruebe con alguna de las páginas siguientes:</strong></p>
			<ul>
				<li><a href="/index.php" title="Ir a la página de inicio">Página de inicio</a></li>
			</ul>
			<p>Si la dificultad persiste, por favor, contacte con el administrador del sistema de este sitio y reporte el error de más abajo.</p>
			<div id="techinfo">
			<p>
				Artículo no encontrado							</p>
						</div>
			</div>
		</div>
		</div>
	</div>
</body>
</html>

[2023-03-25T21:55:35.414+0000] {taskinstance.py:1326} INFO - Marking task as UP_FOR_RETRY. dag_id=get_weather_data_v0, task_id=download_weather_data, execution_date=20230325T200000, start_date=20230325T215534, end_date=20230325T215535
[2023-03-25T21:55:35.435+0000] {standard_task_runner.py:105} ERROR - Failed to execute job 3 for task download_weather_data (Could not retrieve weather data. Response code: 404.
Response message: <!DOCTYPE html>
<html lang="es-es" dir="ltr">
<head>
	<meta charset="utf-8" />
	<title>404 - Artículo no encontrado</title>
	<link href="/templates/system/css/error.css" rel="stylesheet" />
			<!--[if lt IE 9]><script src="/media/jui/js/html5.js"></script><![endif]-->
</head>
<body>
	<div class="error">
		<div id="outline">
		<div id="errorboxoutline">
			<div id="errorboxheader">404 - Artículo no encontrado</div>
			<div id="errorboxbody">
			<p><strong>No puede visitar esta página debido a:</strong></p>
			<ol>
				<li>Un <strong>marcador o favorito caducado</strong></li>
				<li>Un motor de búsquedas que tiene un <strong>listado caducado para este sitio</strong></li>
				<li>Una <strong>dirección mal escrita</strong></li>
				<li>Usted no tiene <strong>acceso</strong> a esta página</li>
				<li>No se pudo encontrar el recurso solicitado.</li>
				<li>Se ha producido un error mientras se procesaba su solicitud.</li>
			</ol>
			<p><strong>Por favor, pruebe con alguna de las páginas siguientes:</strong></p>
			<ul>
				<li><a href="/index.php" title="Ir a la página de inicio">Página de inicio</a></li>
			</ul>
			<p>Si la dificultad persiste, por favor, contacte con el administrador del sistema de este sitio y reporte el error de más abajo.</p>
			<div id="techinfo">
			<p>
				Artículo no encontrado							</p>
						</div>
			</div>
		</div>
		</div>
	</div>
</body>
</html>
; 201)
[2023-03-25T21:55:35.480+0000] {local_task_job.py:212} INFO - Task exited with return code 1
[2023-03-25T21:55:35.521+0000] {taskinstance.py:2585} INFO - 0 downstream tasks scheduled from follow-on schedule check
